[{"name": "unittest.loader._FailedTest.test.test_distinct_characters", "status": "errored", "message": "Failed to import test module: test.test_distinct_characters\nTraceback (most recent call last):\n  File \"C:\\Program Files\\Python312\\Lib\\unittest\\loader.py\", line 394, in _find_test_path\n    module = self._get_module_from_name(name)\n             ^^^^^^^^^^^^^^^^^^^^^^^^^^^^^^^^\n  File \"C:\\Program Files\\Python312\\Lib\\unittest\\loader.py\", line 337, in _get_module_from_name\n    __import__(name)\n  File \"C:\\Users\\shaba\\OneDrive\\Skrivebord\\Python\\Dag2\\Opgaver_dag2\\e12_distinct_characters\\test\\test_distinct_characters.py\", line 3, in <module>\n    import numpy as np\nModuleNotFoundError: No module named 'numpy'\n", "passed": false, "points": [], "backtrace": ["  File \"C:\\Program Files\\Python312\\Lib\\unittest\\case.py\", line 58, in testPartExecutor\n    yield\n", "  File \"C:\\Program Files\\Python312\\Lib\\unittest\\case.py\", line 634, in run\n    self._callTestMethod(testMethod)\n", "  File \"C:\\Program Files\\Python312\\Lib\\unittest\\case.py\", line 589, in _callTestMethod\n    if method() is not None:\n       ^^^^^^^^\n", "  File \"C:\\Program Files\\Python312\\Lib\\unittest\\loader.py\", line 33, in testFailure\n    raise self._exception\n"]}]